2020-02-27 00:42:03,494 ERROR: Exception on /edit_profile [POST] [in /home/atropscooper/Projects/microblog/venv/lib/python3.7/site-packages/flask/app.py:1891]
Traceback (most recent call last):
  File "/home/atropscooper/Projects/microblog/venv/lib/python3.7/site-packages/flask/app.py", line 2446, in wsgi_app
    response = self.full_dispatch_request()
  File "/home/atropscooper/Projects/microblog/venv/lib/python3.7/site-packages/flask/app.py", line 1951, in full_dispatch_request
    rv = self.handle_user_exception(e)
  File "/home/atropscooper/Projects/microblog/venv/lib/python3.7/site-packages/flask/app.py", line 1820, in handle_user_exception
    reraise(exc_type, exc_value, tb)
  File "/home/atropscooper/Projects/microblog/venv/lib/python3.7/site-packages/flask/_compat.py", line 39, in reraise
    raise value
  File "/home/atropscooper/Projects/microblog/venv/lib/python3.7/site-packages/flask/app.py", line 1949, in full_dispatch_request
    rv = self.dispatch_request()
  File "/home/atropscooper/Projects/microblog/venv/lib/python3.7/site-packages/flask/app.py", line 1935, in dispatch_request
    return self.view_functions[rule.endpoint](**req.view_args)
  File "/home/atropscooper/Projects/microblog/venv/lib/python3.7/site-packages/flask_login/utils.py", line 272, in decorated_view
    return func(*args, **kwargs)
  File "/home/atropscooper/Projects/microblog/app/main/routes.py", line 89, in edit_profile
    return redirect(url_for('edit_profile'))
  File "/home/atropscooper/Projects/microblog/venv/lib/python3.7/site-packages/flask/helpers.py", line 370, in url_for
    return appctx.app.handle_url_build_error(error, endpoint, values)
  File "/home/atropscooper/Projects/microblog/venv/lib/python3.7/site-packages/flask/app.py", line 2215, in handle_url_build_error
    reraise(exc_type, exc_value, tb)
  File "/home/atropscooper/Projects/microblog/venv/lib/python3.7/site-packages/flask/_compat.py", line 39, in reraise
    raise value
  File "/home/atropscooper/Projects/microblog/venv/lib/python3.7/site-packages/flask/helpers.py", line 358, in url_for
    endpoint, values, method=method, force_external=external
  File "/home/atropscooper/Projects/microblog/venv/lib/python3.7/site-packages/werkzeug/routing.py", line 2179, in build
    raise BuildError(endpoint, values, method, self)
werkzeug.routing.BuildError: Could not build url for endpoint 'edit_profile'. Did you mean 'main.edit_profile' instead?
2020-02-27 00:43:20,222 ERROR: Exception on /edit_profile [POST] [in /home/atropscooper/Projects/microblog/venv/lib/python3.7/site-packages/flask/app.py:1891]
Traceback (most recent call last):
  File "/home/atropscooper/Projects/microblog/venv/lib/python3.7/site-packages/flask/app.py", line 2446, in wsgi_app
    response = self.full_dispatch_request()
  File "/home/atropscooper/Projects/microblog/venv/lib/python3.7/site-packages/flask/app.py", line 1951, in full_dispatch_request
    rv = self.handle_user_exception(e)
  File "/home/atropscooper/Projects/microblog/venv/lib/python3.7/site-packages/flask/app.py", line 1820, in handle_user_exception
    reraise(exc_type, exc_value, tb)
  File "/home/atropscooper/Projects/microblog/venv/lib/python3.7/site-packages/flask/_compat.py", line 39, in reraise
    raise value
  File "/home/atropscooper/Projects/microblog/venv/lib/python3.7/site-packages/flask/app.py", line 1949, in full_dispatch_request
    rv = self.dispatch_request()
  File "/home/atropscooper/Projects/microblog/venv/lib/python3.7/site-packages/flask/app.py", line 1935, in dispatch_request
    return self.view_functions[rule.endpoint](**req.view_args)
  File "/home/atropscooper/Projects/microblog/venv/lib/python3.7/site-packages/flask_login/utils.py", line 272, in decorated_view
    return func(*args, **kwargs)
  File "/home/atropscooper/Projects/microblog/app/main/routes.py", line 89, in edit_profile
    return redirect(url_for('edit_profile'))
  File "/home/atropscooper/Projects/microblog/venv/lib/python3.7/site-packages/flask/helpers.py", line 370, in url_for
    return appctx.app.handle_url_build_error(error, endpoint, values)
  File "/home/atropscooper/Projects/microblog/venv/lib/python3.7/site-packages/flask/app.py", line 2215, in handle_url_build_error
    reraise(exc_type, exc_value, tb)
  File "/home/atropscooper/Projects/microblog/venv/lib/python3.7/site-packages/flask/_compat.py", line 39, in reraise
    raise value
  File "/home/atropscooper/Projects/microblog/venv/lib/python3.7/site-packages/flask/helpers.py", line 358, in url_for
    endpoint, values, method=method, force_external=external
  File "/home/atropscooper/Projects/microblog/venv/lib/python3.7/site-packages/werkzeug/routing.py", line 2179, in build
    raise BuildError(endpoint, values, method, self)
werkzeug.routing.BuildError: Could not build url for endpoint 'edit_profile'. Did you mean 'main.edit_profile' instead?
2020-02-27 00:43:27,375 INFO: Microblog startup [in /home/atropscooper/Projects/microblog/app/__init__.py:68]
2020-02-27 00:43:33,388 ERROR: Exception on /edit_profile [POST] [in /home/atropscooper/Projects/microblog/venv/lib/python3.7/site-packages/flask/app.py:1891]
Traceback (most recent call last):
  File "/home/atropscooper/Projects/microblog/venv/lib/python3.7/site-packages/flask/app.py", line 2446, in wsgi_app
    response = self.full_dispatch_request()
  File "/home/atropscooper/Projects/microblog/venv/lib/python3.7/site-packages/flask/app.py", line 1951, in full_dispatch_request
    rv = self.handle_user_exception(e)
  File "/home/atropscooper/Projects/microblog/venv/lib/python3.7/site-packages/flask/app.py", line 1820, in handle_user_exception
    reraise(exc_type, exc_value, tb)
  File "/home/atropscooper/Projects/microblog/venv/lib/python3.7/site-packages/flask/_compat.py", line 39, in reraise
    raise value
  File "/home/atropscooper/Projects/microblog/venv/lib/python3.7/site-packages/flask/app.py", line 1949, in full_dispatch_request
    rv = self.dispatch_request()
  File "/home/atropscooper/Projects/microblog/venv/lib/python3.7/site-packages/flask/app.py", line 1935, in dispatch_request
    return self.view_functions[rule.endpoint](**req.view_args)
  File "/home/atropscooper/Projects/microblog/venv/lib/python3.7/site-packages/flask_login/utils.py", line 272, in decorated_view
    return func(*args, **kwargs)
  File "/home/atropscooper/Projects/microblog/app/main/routes.py", line 89, in edit_profile
    return redirect(url_for('edit_profile'))
  File "/home/atropscooper/Projects/microblog/venv/lib/python3.7/site-packages/flask/helpers.py", line 370, in url_for
    return appctx.app.handle_url_build_error(error, endpoint, values)
  File "/home/atropscooper/Projects/microblog/venv/lib/python3.7/site-packages/flask/app.py", line 2215, in handle_url_build_error
    reraise(exc_type, exc_value, tb)
  File "/home/atropscooper/Projects/microblog/venv/lib/python3.7/site-packages/flask/_compat.py", line 39, in reraise
    raise value
  File "/home/atropscooper/Projects/microblog/venv/lib/python3.7/site-packages/flask/helpers.py", line 358, in url_for
    endpoint, values, method=method, force_external=external
  File "/home/atropscooper/Projects/microblog/venv/lib/python3.7/site-packages/werkzeug/routing.py", line 2179, in build
    raise BuildError(endpoint, values, method, self)
werkzeug.routing.BuildError: Could not build url for endpoint 'edit_profile'. Did you mean 'main.edit_profile' instead?
2020-02-27 00:44:05,867 INFO: Microblog startup [in /home/atropscooper/Projects/microblog/app/__init__.py:68]
2020-02-27 00:44:30,330 ERROR: Exception on /auth/login [POST] [in /home/atropscooper/Projects/microblog/venv/lib/python3.7/site-packages/flask/app.py:1891]
Traceback (most recent call last):
  File "/home/atropscooper/Projects/microblog/venv/lib/python3.7/site-packages/flask/app.py", line 2446, in wsgi_app
    response = self.full_dispatch_request()
  File "/home/atropscooper/Projects/microblog/venv/lib/python3.7/site-packages/flask/app.py", line 1951, in full_dispatch_request
    rv = self.handle_user_exception(e)
  File "/home/atropscooper/Projects/microblog/venv/lib/python3.7/site-packages/flask/app.py", line 1820, in handle_user_exception
    reraise(exc_type, exc_value, tb)
  File "/home/atropscooper/Projects/microblog/venv/lib/python3.7/site-packages/flask/_compat.py", line 39, in reraise
    raise value
  File "/home/atropscooper/Projects/microblog/venv/lib/python3.7/site-packages/flask/app.py", line 1949, in full_dispatch_request
    rv = self.dispatch_request()
  File "/home/atropscooper/Projects/microblog/venv/lib/python3.7/site-packages/flask/app.py", line 1935, in dispatch_request
    return self.view_functions[rule.endpoint](**req.view_args)
  File "/home/atropscooper/Projects/microblog/app/auth/routes.py", line 22, in login
    return redirect(url_for('login'))
  File "/home/atropscooper/Projects/microblog/venv/lib/python3.7/site-packages/flask/helpers.py", line 370, in url_for
    return appctx.app.handle_url_build_error(error, endpoint, values)
  File "/home/atropscooper/Projects/microblog/venv/lib/python3.7/site-packages/flask/app.py", line 2215, in handle_url_build_error
    reraise(exc_type, exc_value, tb)
  File "/home/atropscooper/Projects/microblog/venv/lib/python3.7/site-packages/flask/_compat.py", line 39, in reraise
    raise value
  File "/home/atropscooper/Projects/microblog/venv/lib/python3.7/site-packages/flask/helpers.py", line 358, in url_for
    endpoint, values, method=method, force_external=external
  File "/home/atropscooper/Projects/microblog/venv/lib/python3.7/site-packages/werkzeug/routing.py", line 2179, in build
    raise BuildError(endpoint, values, method, self)
werkzeug.routing.BuildError: Could not build url for endpoint 'login'. Did you mean 'auth.login' instead?
