2020-02-27 00:50:06,897 ERROR: Exception on /auth/reset_password_request [POST] [in /home/atropscooper/Projects/microblog/venv/lib/python3.7/site-packages/flask/app.py:1891]
Traceback (most recent call last):
  File "/home/atropscooper/Projects/microblog/venv/lib/python3.7/site-packages/flask/app.py", line 2446, in wsgi_app
    response = self.full_dispatch_request()
  File "/home/atropscooper/Projects/microblog/venv/lib/python3.7/site-packages/flask/app.py", line 1951, in full_dispatch_request
    rv = self.handle_user_exception(e)
  File "/home/atropscooper/Projects/microblog/venv/lib/python3.7/site-packages/flask/app.py", line 1820, in handle_user_exception
    reraise(exc_type, exc_value, tb)
  File "/home/atropscooper/Projects/microblog/venv/lib/python3.7/site-packages/flask/_compat.py", line 39, in reraise
    raise value
  File "/home/atropscooper/Projects/microblog/venv/lib/python3.7/site-packages/flask/app.py", line 1949, in full_dispatch_request
    rv = self.dispatch_request()
  File "/home/atropscooper/Projects/microblog/venv/lib/python3.7/site-packages/flask/app.py", line 1935, in dispatch_request
    return self.view_functions[rule.endpoint](**req.view_args)
  File "/home/atropscooper/Projects/microblog/app/auth/routes.py", line 61, in reset_password_request
    send_password_reset_email(user)
  File "/home/atropscooper/Projects/microblog/app/auth/email.py", line 13, in send_password_reset_email
    user=user, token=token))
  File "/home/atropscooper/Projects/microblog/venv/lib/python3.7/site-packages/flask/templating.py", line 140, in render_template
    ctx.app,
  File "/home/atropscooper/Projects/microblog/venv/lib/python3.7/site-packages/flask/templating.py", line 120, in _render
    rv = template.render(context)
  File "/home/atropscooper/Projects/microblog/venv/lib/python3.7/site-packages/jinja2/environment.py", line 1090, in render
    self.environment.handle_exception()
  File "/home/atropscooper/Projects/microblog/venv/lib/python3.7/site-packages/jinja2/environment.py", line 832, in handle_exception
    reraise(*rewrite_traceback_stack(source=source))
  File "/home/atropscooper/Projects/microblog/venv/lib/python3.7/site-packages/jinja2/_compat.py", line 28, in reraise
    raise value.with_traceback(tb)
  File "/home/atropscooper/Projects/microblog/app/templates/email/reset_password.html", line 9, in top-level template code
    <p>{{ url_for('reset_password', token=token, _external=True) }}</p>
  File "/home/atropscooper/Projects/microblog/venv/lib/python3.7/site-packages/flask/helpers.py", line 370, in url_for
    return appctx.app.handle_url_build_error(error, endpoint, values)
  File "/home/atropscooper/Projects/microblog/venv/lib/python3.7/site-packages/flask/app.py", line 2215, in handle_url_build_error
    reraise(exc_type, exc_value, tb)
  File "/home/atropscooper/Projects/microblog/venv/lib/python3.7/site-packages/flask/_compat.py", line 39, in reraise
    raise value
  File "/home/atropscooper/Projects/microblog/venv/lib/python3.7/site-packages/flask/helpers.py", line 358, in url_for
    endpoint, values, method=method, force_external=external
  File "/home/atropscooper/Projects/microblog/venv/lib/python3.7/site-packages/werkzeug/routing.py", line 2179, in build
    raise BuildError(endpoint, values, method, self)
werkzeug.routing.BuildError: Could not build url for endpoint 'reset_password' with values ['token']. Did you mean 'auth.reset_password' instead?
2020-02-27 00:51:18,787 INFO: Microblog startup [in /home/atropscooper/Projects/microblog/app/__init__.py:68]
2020-03-14 18:20:34,450 INFO: Microblog startup [in /home/atrops/microblog/app/__init__.py:68]
2020-03-14 18:20:34,452 INFO: Microblog startup [in /home/atrops/microblog/app/__init__.py:68]
