2020-02-27 00:45:22,849 ERROR: Exception on /auth/login [POST] [in /home/atropscooper/Projects/microblog/venv/lib/python3.7/site-packages/flask/app.py:1891]
Traceback (most recent call last):
  File "/home/atropscooper/Projects/microblog/venv/lib/python3.7/site-packages/flask/app.py", line 2446, in wsgi_app
    response = self.full_dispatch_request()
  File "/home/atropscooper/Projects/microblog/venv/lib/python3.7/site-packages/flask/app.py", line 1951, in full_dispatch_request
    rv = self.handle_user_exception(e)
  File "/home/atropscooper/Projects/microblog/venv/lib/python3.7/site-packages/flask/app.py", line 1820, in handle_user_exception
    reraise(exc_type, exc_value, tb)
  File "/home/atropscooper/Projects/microblog/venv/lib/python3.7/site-packages/flask/_compat.py", line 39, in reraise
    raise value
  File "/home/atropscooper/Projects/microblog/venv/lib/python3.7/site-packages/flask/app.py", line 1949, in full_dispatch_request
    rv = self.dispatch_request()
  File "/home/atropscooper/Projects/microblog/venv/lib/python3.7/site-packages/flask/app.py", line 1935, in dispatch_request
    return self.view_functions[rule.endpoint](**req.view_args)
  File "/home/atropscooper/Projects/microblog/app/auth/routes.py", line 22, in login
    return redirect(url_for('auth.login'))
  File "/home/atropscooper/Projects/microblog/venv/lib/python3.7/site-packages/flask/helpers.py", line 370, in url_for
    return appctx.app.handle_url_build_error(error, endpoint, values)
  File "/home/atropscooper/Projects/microblog/venv/lib/python3.7/site-packages/flask/app.py", line 2215, in handle_url_build_error
    reraise(exc_type, exc_value, tb)
  File "/home/atropscooper/Projects/microblog/venv/lib/python3.7/site-packages/flask/_compat.py", line 39, in reraise
    raise value
  File "/home/atropscooper/Projects/microblog/venv/lib/python3.7/site-packages/flask/helpers.py", line 358, in url_for
    endpoint, values, method=method, force_external=external
  File "/home/atropscooper/Projects/microblog/venv/lib/python3.7/site-packages/werkzeug/routing.py", line 2179, in build
    raise BuildError(endpoint, values, method, self)
werkzeug.routing.BuildError: Could not build url for endpoint 'login'. Did you mean 'auth.login' instead?
2020-02-27 00:45:33,439 INFO: Microblog startup [in /home/atropscooper/Projects/microblog/app/__init__.py:68]
2020-02-27 00:46:00,957 ERROR: Exception on /auth/reset_password_request [POST] [in /home/atropscooper/Projects/microblog/venv/lib/python3.7/site-packages/flask/app.py:1891]
Traceback (most recent call last):
  File "/home/atropscooper/Projects/microblog/venv/lib/python3.7/site-packages/flask/app.py", line 2446, in wsgi_app
    response = self.full_dispatch_request()
  File "/home/atropscooper/Projects/microblog/venv/lib/python3.7/site-packages/flask/app.py", line 1951, in full_dispatch_request
    rv = self.handle_user_exception(e)
  File "/home/atropscooper/Projects/microblog/venv/lib/python3.7/site-packages/flask/app.py", line 1820, in handle_user_exception
    reraise(exc_type, exc_value, tb)
  File "/home/atropscooper/Projects/microblog/venv/lib/python3.7/site-packages/flask/_compat.py", line 39, in reraise
    raise value
  File "/home/atropscooper/Projects/microblog/venv/lib/python3.7/site-packages/flask/app.py", line 1949, in full_dispatch_request
    rv = self.dispatch_request()
  File "/home/atropscooper/Projects/microblog/venv/lib/python3.7/site-packages/flask/app.py", line 1935, in dispatch_request
    return self.view_functions[rule.endpoint](**req.view_args)
  File "/home/atropscooper/Projects/microblog/app/auth/routes.py", line 61, in reset_password_request
    send_password_reset_email(user)
  File "/home/atropscooper/Projects/microblog/app/auth/email.py", line 6, in send_password_reset_email
    token = user.get_reset_password_token()
  File "/home/atropscooper/Projects/microblog/app/models.py", line 68, in get_reset_password_token
    return jwt.encode(
AttributeError: module 'jwt' has no attribute 'encode'
2020-02-27 00:47:59,103 INFO: Microblog startup [in /home/atropscooper/Projects/microblog/app/__init__.py:68]
2020-02-27 00:48:08,291 ERROR: Exception on /auth/reset_password_request [POST] [in /home/atropscooper/Projects/microblog/venv/lib/python3.7/site-packages/flask/app.py:1891]
Traceback (most recent call last):
  File "/home/atropscooper/Projects/microblog/venv/lib/python3.7/site-packages/flask/app.py", line 2446, in wsgi_app
    response = self.full_dispatch_request()
  File "/home/atropscooper/Projects/microblog/venv/lib/python3.7/site-packages/flask/app.py", line 1951, in full_dispatch_request
    rv = self.handle_user_exception(e)
  File "/home/atropscooper/Projects/microblog/venv/lib/python3.7/site-packages/flask/app.py", line 1820, in handle_user_exception
    reraise(exc_type, exc_value, tb)
  File "/home/atropscooper/Projects/microblog/venv/lib/python3.7/site-packages/flask/_compat.py", line 39, in reraise
    raise value
  File "/home/atropscooper/Projects/microblog/venv/lib/python3.7/site-packages/flask/app.py", line 1949, in full_dispatch_request
    rv = self.dispatch_request()
  File "/home/atropscooper/Projects/microblog/venv/lib/python3.7/site-packages/flask/app.py", line 1935, in dispatch_request
    return self.view_functions[rule.endpoint](**req.view_args)
  File "/home/atropscooper/Projects/microblog/app/auth/routes.py", line 61, in reset_password_request
    send_password_reset_email(user)
  File "/home/atropscooper/Projects/microblog/app/auth/email.py", line 6, in send_password_reset_email
    token = user.get_reset_password_token()
  File "/home/atropscooper/Projects/microblog/app/models.py", line 68, in get_reset_password_token
    return jwt.encode(
AttributeError: module 'jwt' has no attribute 'encode'
2020-02-27 00:49:21,873 INFO: Microblog startup [in /home/atropscooper/Projects/microblog/app/__init__.py:68]
2020-02-27 00:49:30,108 ERROR: Exception on /auth/reset_password_request [POST] [in /home/atropscooper/Projects/microblog/venv/lib/python3.7/site-packages/flask/app.py:1891]
Traceback (most recent call last):
  File "/home/atropscooper/Projects/microblog/venv/lib/python3.7/site-packages/flask/app.py", line 2446, in wsgi_app
    response = self.full_dispatch_request()
  File "/home/atropscooper/Projects/microblog/venv/lib/python3.7/site-packages/flask/app.py", line 1951, in full_dispatch_request
    rv = self.handle_user_exception(e)
  File "/home/atropscooper/Projects/microblog/venv/lib/python3.7/site-packages/flask/app.py", line 1820, in handle_user_exception
    reraise(exc_type, exc_value, tb)
  File "/home/atropscooper/Projects/microblog/venv/lib/python3.7/site-packages/flask/_compat.py", line 39, in reraise
    raise value
  File "/home/atropscooper/Projects/microblog/venv/lib/python3.7/site-packages/flask/app.py", line 1949, in full_dispatch_request
    rv = self.dispatch_request()
  File "/home/atropscooper/Projects/microblog/venv/lib/python3.7/site-packages/flask/app.py", line 1935, in dispatch_request
    return self.view_functions[rule.endpoint](**req.view_args)
  File "/home/atropscooper/Projects/microblog/app/auth/routes.py", line 61, in reset_password_request
    send_password_reset_email(user)
  File "/home/atropscooper/Projects/microblog/app/auth/email.py", line 8, in send_password_reset_email
    sender=app.config['ADMINS'][0],
NameError: name 'app' is not defined
2020-02-27 00:50:00,001 INFO: Microblog startup [in /home/atropscooper/Projects/microblog/app/__init__.py:68]
